<?xml version="1.0" ?>

<robot name="herbert2_robot"
      xmlns:xacro="http://ros.org/wiki/xacro">


    <!--
        Polar Robot Movement:
            +X: Forward
            -X: Reverse 
            +Y: Right
            -Y: Left
    -->

    <material name="blue">
        <color rgba="0 0 0.8 0.5"/>
    </material>

    <material name="green">
        <color rgba="0 0.8 0 0.5"/>
    </material>

    <material name="red">
        <color rgba="1.0 0.0 0.0 1.0"/>
    </material>

    <material name="white">
        <color rgba="1 1 1 1"/>
    </material>

    <!--  Herbert2 Footprint Link   -->

    <link name="footprint_link"/>
    
    <!--  Base Link and Joint -->

    <joint name="base_joint" type="fixed">
        <parent link="footprint_link"/>
        <child link="base_link"/>
        <origin xyz="0 0.0 0.0" rpy="0 0 0"/>
    </joint>

    <link name="base_link">
        <visual>
            <geometry>
                <cylinder radius="0.180" length="0.006"/>
            </geometry>
            <material name="blue"/>
            <origin rpy="0 0 0" xyz="0 0 0"/>
        </visual>
    </link>

    <!--  Motor A Link and Joint -->

    <link name="motor_a_link">
        <visual>
            <geometry>
                <cylinder length="0.036" radius="0.05"/>
            </geometry>
            <origin rpy="0 1.57075 0" 
                    xyz="0.150 0 0"/>
            <material name="green"/>
        </visual>
    </link>

    <joint name="motor_a_joint" type="continuous">
        <parent link="base_link"/>
        <child link="motor_a_link"/>
        <origin xyz="0 0 0"
                rpy="0 0 1.04719755"/>
        <axis xyz="1 0 0"/>
    </joint>

    <!--  Motor B Link and Joint -->
    
    <link name="motor_b_link">
        <visual>
            <geometry>
                <cylinder length="0.036" radius="0.05"/>
            </geometry>
            <origin rpy="0 1.57075 0"
                    xyz="0.150 0 0"/>
            <material name="blue"/>
        </visual>
    </link>
    
    <joint name="motor_b_joint" type="continuous">
        <parent link="base_link"/>
        <child link="motor_b_link"/>
        <origin xyz="0 0 0"
                rpy="0 0 3.1415926"/>
        <axis xyz="1 0 0"/>
    </joint>
      
    <!-- ========= Motor C Link and Joint ==================== -->
    
    <link name="motor_c_link">
        <visual>
            <geometry>
                <cylinder length="0.036" radius="0.05"/>
            </geometry>
            <origin rpy="0 1.57075 0" 
                    xyz="0.150 0 0"/>
            <material name="red"/>
        </visual>
    </link>

    <joint name="motor_c_joint" type="continuous">
        <parent link="base_link"/>
        <child link="motor_c_link"/>
        <origin xyz="0 0 0"
                rpy="0 0 -1.04719755"/>
        <axis xyz="1 0 0"/>
    </joint>

    <!-- ========== RPLidar ================================== -->
    
    <link name="rplidar_link">
        <visual>
            <origin xyz="0 0 0.0" rpy="0 0 0"/>
            <geometry> 
                <cylinder radius="0.030" length="0.060"/>
            </geometry>
            <material name="white"/>
        </visual>    
    </link>

    <joint name="scan_joint" type="fixed">
        <parent link="base_link"/>
        <child link="rplidar_link"/>
        <origin xyz="0.0 0.0 0.0" rpy="0 0 0"/>
    </joint>

    <!--  IMU Link and Joint -->

    <link name="imu_link"/>

    <joint name="imu_joint" type="fixed">
        <parent link="base_link"/>
        <child link="imu_link"/>
        <origin xyz="-0.032 0 0.172" rpy="0 0 0"/>
    </joint>

</robot>
